Workbook

Sheet Como usar
A1: Planilha de cruzamento — o arquivo-mestre da pauta
A2: Jornalismo Investigativo na Prática · material bônus · alinhada aos roteiros das aulas e aos insertos de tela · setembro de 2026
A4: Como ler as cores
A5: Cabeçalho azul | B5: Você preenche.
A6: Cabeçalho cinza (auto) | B6: Fórmula automática. Não digite nessas colunas.
A7: Linha em itálico | B7: Exemplo fictício. Exclua as linhas inteiras (botão direito > Excluir) antes de usar na sua pauta. Na aba Ética da pauta, apague só o texto em itálico.
A8: Vermelho ou laranja | B8: Alerta automático. Cada alerta é uma pergunta, não uma conclusão (aula 4.6).
A9: CNPJ em vermelho | B9: O CNPJ não tem 14 caracteres. Tire pontos, barra e traço.
A11: As abas, na ordem do curso
A12: Aba | B12: Para que serve | C12: Aulas e insertos | D12: Colunas, na ordem | E12: Pronta até a linha
A13: Bombas | B13: As bombas que chegaram e qual delas vira a pauta do curso. | C13: 1.1 | D13: bomba, quem mandou, documento verificável?, interesse público? | E13: 51
A14: Linha do tempo | B14: Os fatos em ordem de data, cada um com documento e fonte. É o arquivo-mestre. | C14: 1.3, 4.1, OSINT 6.3, 7.2 | D14: data, fato, documento, fonte | E14: 501
A15: Ética da pauta | B15: Interesse público em duas linhas, conflito de interesse e quem não será exposto. | C15: 1.4 | D15: uma linha por item: interesse público, conflito de interesse, quem não será exposto | E15: 4
A16: Fontes | B16: As fontes possíveis, com a matriz de credibilidade e a ordem de abordagem. Só código ou descrição, nunca o nome. | C16: 2.1, 2.2 | D16: fonte, tipo, acesso, interesse, histórico, corroboração, ordem de abordagem | E16: 51
A17: Log | B17: De onde veio cada dado e quando: documentos, bases, pedidos, arquivos, respostas, hashes. | C17: 2.3, 3.2, 3.5, 4.6, OSINT 6.1, 6.6 e 6.7, 6.2 a 6.4 | D17: origem, data e hora, ferramenta, arquivo, código ou protocolo, hash | E17: 501
A18: Risco | B18: A matriz de risco da pauta, com a prioridade de cada risco. | C18: 2.4 | D18: risco, probabilidade, impacto, medida | E18: 51
A19: Documentos | B19: Os documentos de que a pauta precisa, quem tem e se já estão publicados. | C19: 3.1 | D19: documento, quem tem, já está publicado?, onde | E19: 101
A20: Prazos LAI | B20: O calendário de cada pedido: prazo do órgão, recurso e reclamação. | C20: 3.2 a 3.5 | D20: protocolo, órgão, esfera, pedido, data do pedido e as datas seguintes | E20: 101
A21: Pagamentos | B21: Empenhos e pagamentos, com o cruzamento do inserto 4.6. | C21: 4.2, 4.6 | D21: CNPJ do credor, nome, valor, data, fonte | E21: 2001
A22: Contratos | B22: Contratos, com data de abertura da empresa, sanção e aditivos. | C22: 4.2, 4.6 | D22: CNPJ do fornecedor, órgão, objeto, valor, modalidade, data do contrato, data de abertura (fórmula), vigência | E22: 1001
A23: Sancoes | B23: CEIS, CNEP, CEPIM e outros cadastros. “Não consta” também é resultado. | C23: 4.2 | D23: CNPJ, tipo de sanção, abrangência, período (início e fim) | E23: 301
A24: Empresas | B24: Uma linha por CNPJ, com o sinal e o resumo do que as outras abas encontraram. | C24: 4.3, 4.6 | D24: CNPJ, razão social, data de abertura, CNAE, capital social, endereço, sinal | E24: 501
... A30: Perfis | B30: Os perfis oficiais da pauta e a regra de observação. | C30: OSINT 6.5, 6.7 | D30: nome, rede, link, data de criação, cópia arquivada | E30: 201
A31: Listas | B31: Opções das listas suspensas e a frase de cada fase processual. | C31: — | D31: — | E31: —
A33: Regras de uso
A34: 1 | B34: O cabeçalho fica na linha 1 e os dados começam na linha 2. Por isso as fórmulas mostradas nas aulas, como =PROCX(A2;...), funcionam do jeito que aparecem na tela.
A35: 2 | B35: O CNPJ é a chave. Fica sempre na coluna A de Pagamentos, Contratos, Sancoes, Empresas, Socios e Eleitoral, como texto, com 14 caracteres, sem pontos, barra ou traço. Texto guarda o zero à esquerda e aceita o CNPJ com letras (aula 4.3). Copiou com pontos? Limpe numa coluna ao lado com =SUBSTITUIR(SUBSTITUIR(SUBSTITUIR(A2;".";"");"/";"");"-";"") (aula 4.6) e cole o resultado como valor.
A36: 3 | B36: Pessoa se cruza pelo nome mais os dígitos visíveis do CPF. Nunca só pelo nome (aula 4.6).
A37: 4 | B37: Todo dado entra com fonte. No Log, dê a cada registro um ID (L001, L002...) e cite esse ID na coluna Fonte das outras abas. É o que responde à pergunta “como você sabe disso?”.
A38: 5 | B38: Vínculo não é culpa. Cada alerta vira uma pergunta para os documentos e para as pessoas envolvidas (aula 4.6).
A39: 6 | B39: Fonte humana entra só por código (F1, F2) ou por descrição. Nunca o nome verdadeiro (aula 2.2).
A40: 7 | B40: Na tela, tarje CPF, endereço, telefone e o nome de sócio pessoa física, de servidor sem cargo de chefia e de cidadão comum, salvo quando forem o centro de um fato já publicado.
A41: 8 | B41: As aulas mostram PROCX. Esta planilha usa ÍNDICE e CORRESP, que dão o mesmo resultado e funcionam em qualquer Excel, no LibreOffice e no Google Planilhas. A tabela abaixo mostra a equivalência.
A42: 9 | B42: As abas Socios e Sancoes não têm acento para que as fórmulas das aulas funcionem como mostradas.
A43: 10 | B43: A aba Prazos LAI conta dias corridos a partir da data de hoje do computador. Depois da 1ª instância, segue os degraus do governo federal; em estados e municípios, confira a norma local (aula 3.3).
A44: 11 | B44: As fórmulas vão até a linha indicada na tabela das abas. Para mais linhas, copie a última linha da aba para baixo.
A45: 12 | B45: OSINT 6.1 a 6.7 são as aulas do módulo de fontes abertas, que substitui a aula 4.7.
... A47: 14 | B47: Os exemplos contam uma história fictícia de ponta a ponta, em Cidade Exemplo: siga os CNPJs da Alimentos Modelo e da Gráfica Exemplo pelas abas para ver os cruzamentos. Nomes, CNPJs, CPFs, protocolos, processos e links não existem.
A49: As fórmulas das aulas nesta planilha
A50: Na aula | B50: Nesta planilha | C50: Onde
...

Sheet Bombas
A1: Bomba | B1: Quem mandou | C1: Documento verificável? | D1: Interesse público? | E1: Escolhida para o curso? | F1: Observações
A2: Print: o secretário de saúde superfatura remédio | B2: Grupo de WhatsApp, sem autor | C2: Não | D2: Sim | E2: Não | F2: EXEMPLO — fica na gaveta até aparecer um documento
A3: Áudio: o prefeito tem apartamento em Miami | B3: “O primo de alguém” | C3: Não | D3: Depende de onde veio o dinheiro | E3: Não | F3: EXEMPLO — curiosidade até prova em contrário
A4: Empresa aberta cinco meses antes ganha contrato de merenda sem licitação em Cidade Exemplo | B4: Servidor da secretaria (F1) | C4: Sim: extrato do contrato no PNCP | D4: Sim: dinheiro da merenda escolar | E4: Sim | F4: EXEMPLO — PAUTA DO CURSO

Sheet Linha do tempo
A1: Data | B1: Fato | C1: Documento | D1: Fonte | E1: Link | F1: Quem (pessoa ou empresa) | G1: Tipo | H1: Fato, indício ou versão? | I1: Registro no Log (auto) | J1: Observações
A2: 45550 | B2: Fulano de Tal doa R$ 20 mil à campanha de Sicrano Candidato a vereador | C2: Prestação de contas da campanha de 2024 | D2: L006 | F2: Fulano de Tal; Sicrano Candidato | G2: Campanha ou eleição | H2: Fato | I2: =IF(D2="","",IFERROR(IF(INDEX(Log!$I:$I,MATCH(D2,Log!$G:$G,0))&""="",INDEX(Log!$A:$A,MATCH(D2,Log!$G:$G,0))&"",INDEX(Log!$I:$I,MATCH(D2,Log!$G:$G,0))&""),IF(AND(LEN(D2)=4,LEFT(D2,1)="L",ISNUMBER(VALUE(MID(D2,2,3)))),"ID não encontrado no Log",""))) -> Bens, doadores e fornecedores de campanha de Sicrano Candidato (2024 e 2026) | J2: EXEMPLO — exclua esta linha
A3: 45555 | B3: Gráfica Exemplo recebe R$ 15 mil da campanha de Sicrano Candidato por santinhos e adesivos | C3: Prestação de contas da campanha de 2024 | D3: L006 | F3: Gráfica Exemplo Ltda; Sicrano Candidato | G3: Campanha ou eleição | H3: Fato | I3: =IF(D3="","",IFERROR(IF(INDEX(Log!$I:$I,MATCH(D3,Log!$G:$G,0))&""="",INDEX(Log!$A:$A,MATCH(D3,Log!$G:$G,0))&"",INDEX(Log!$I:$I,MATCH(D3,Log!$G:$G,0))&""),IF(AND(LEN(D3)=4,LEFT(D3,1)="L",ISNUMBER(VALUE(MID(D3,2,3)))),"ID não encontrado no Log",""))) -> Bens, doadores e fornecedores de campanha de Sicrano Candidato (2024 e 2026) | J3: EXEMPLO — exclua esta linha
A4: 45672 | B4: Fulano de Tal é nomeado assessor parlamentar no gabinete de Sicrano Candidato | C4: Ato de nomeação no diário oficial da Câmara | D4: L002 | F4: Fulano de Tal | G4: Nomeação ou exoneração | H4: Fato | I4: =IF(D4="","",IFERROR(IF(INDEX(Log!$I:$I,MATCH(D4,Log!$G:$G,0))&""="",INDEX(Log!$A:$A,MATCH(D4,Log!$G:$G,0))&"",INDEX(Log!$I:$I,MATCH(D4,Log!$G:$G,0))&""),IF(AND(LEN(D4)=4,LEFT(D4,1)="L",ISNUMBER(VALUE(MID(D4,2,3)))),"ID não encontrado no Log",""))) -> Ato de nomeação de Fulano de Tal (15/01/2025) | J4: EXEMPLO — exclua esta linha
A5: 45719 | B5: A Câmara contrata a Gráfica Exemplo por pregão, por R$ 95 mil | C5: Extrato do contrato 008/2025 | D5: L003 | F5: Gráfica Exemplo Ltda | G5: Contrato ou aditivo | H5: Fato | I5: =IF(D5="","",IFERROR(IF(INDEX(Log!$I:$I,MATCH(D5,Log!$G:$G,0))&""="",INDEX(Log!$A:$A,MATCH(D5,Log!$G:$G,0))&"",INDEX(Log!$I:$I,MATCH(D5,Log!$G:$G,0))&""),IF(AND(LEN(D5)=4,LEFT(D5,1)="L",ISNUMBER(VALUE(MID(D5,2,3)))),"ID não encontrado no Log",""))) -> Extratos dos contratos 045/2025 (dispensa) e 008/2025 (pregão) | J5: EXEMPLO — exclua esta linha
A6: 45726 | B6: Alimentos Modelo Ltda é aberta, com Fulano de Tal como sócio-administrador | C6: Cadastro CNPJ e quadro de sócios | D6: L001 | F6: Alimentos Modelo Ltda | G6: Empresa | H6: Fato | I6: =IF(D6="","",IFERROR(IF(INDEX(Log!$I:$I,MATCH(D6,Log!$G:$G,0))&""="",INDEX(Log!$A:$A,MATCH(D6,Log!$G:$G,0))&"",INDEX(Log!$I:$I,MATCH(D6,Log!$G:$G,0))&""),IF(AND(LEN(D6)=4,LEFT(D6,1)="L",ISNUMBER(VALUE(MID(D6,2,3)))),"ID não encontrado no Log",""))) -> Cadastro CNPJ e quadro de sócios da Alimentos Modelo, da Construtora Exemplo e da Gráfica Exemplo | J6: EXEMPLO — exclua esta linha
A7: 45839 | B7: Segundo fonte em off (F1), a contratação foi acertada antes do processo | C7: Nenhum ainda | D7: L011 | F7: Alimentos Modelo Ltda | G7: Contrato ou aditivo | H7: Versão | I7: =IF(D7="","",IFERROR(IF(INDEX(Log!$I:$I,MATCH(D7,Log!$G:$G,0))&""="",INDEX(Log!$A:$A,MATCH(D7,Log!$G:$G,0))&"",INDEX(Log!$I:$I,MATCH(D7,Log!$G:$G,0))&""),IF(AND(LEN(D7)=4,LEFT(D7,1)="L",ISNUMBER(VALUE(MID(D7,2,3)))),"ID não encontrado no Log",""))) -> Conversa em off com F1 sobre a contratação da merenda | J7: EXEMPLO — sem documento, é lenda: não vai ao ar sem confirmação independente
A8: 45889 | B8: Secretaria de Educação contrata a Alimentos Modelo por dispensa, por R$ 480 mil | C8: Extrato do contrato 045/2025 | D8: L003 | F8: Alimentos Modelo Ltda | G8: Contrato ou aditivo | H8: Fato | I8: =IF(D8="","",IFERROR(IF(INDEX(Log!$I:$I,MATCH(D8,Log!$G:$G,0))&""="",INDEX(Log!$A:$A,MATCH(D8,Log!$G:$G,0))&"",INDEX(Log!$I:$I,MATCH(D8,Log!$G:$G,0))&""),IF(AND(LEN(D8)=4,LEFT(D8,1)="L",ISNUMBER(VALUE(MID(D8,2,3)))),"ID não encontrado no Log",""))) -> Extratos dos contratos 045/2025 (dispensa) e 008/2025 (pregão) | J8: EXEMPLO — exclua esta linha
A9: 45930 | B9: Primeiro pagamento à Alimentos Modelo: R$ 120 mil | C9: Ordem bancária 2025OB000456 | D9: L004 | F9: Alimentos Modelo Ltda | G9: Pagamento | H9: Fato | I9: =IF(D9="","",IFERROR(IF(INDEX(Log!$I:$I,MATCH(D9,Log!$G:$G,0))&""="",INDEX(Log!$A:$A,MATCH(D9,Log!$G:$G,0))&"",INDEX(Log!$I:$I,MATCH(D9,Log!$G:$G,0))&""),IF(AND(LEN(D9)=4,LEFT(D9,1)="L",ISNUMBER(VALUE(MID(D9,2,3)))),"ID não encontrado no Log",""))) -> Empenhos e pagamentos a fornecedores, de 2023 a 2025 | J9: EXEMPLO — exclua esta linha
A10: 46154 | B10: Justiça recebe ação de improbidade sobre a contratação | C10: Decisão de recebimento da ação | D10: L007 | F10: Alimentos Modelo Ltda | G10: Processo judicial | H10: Fato | I10: =IF(D10="","",IFERROR(IF(INDEX(Log!$I:$I,MATCH(D10,Log!$G:$G,0))&""="",INDEX(Log!$A:$A,MATCH(D10,Log!$G:$G,0))&"",INDEX(Log!$I:$I,MATCH(D10,Log!$G:$G,0))&""),IF(AND(LEN(D10)=4,LEFT(D10,1)="L",ISNUMBER(VALUE(MID(D10,2,3)))),"ID não encontrado no Log",""))) -> Decisão que recebeu a ação de improbidade | J10: EXEMPLO — exclua esta linha
A11: 46289 | B11: Pedido de posicionamento enviado à empresa, ao gabinete do vereador e à Câmara | C11: E-mail com as perguntas e o prazo | D11: L012 | F11: Alimentos Modelo Ltda; Sicrano Candidato | G11: Pedido de posicionamento | H11: Fato | I11: =IF(D11="","",IFERROR(IF(INDEX(Log!$I:$I,MATCH(D11,Log!$G:$G,0))&""="",INDEX(Log!$A:$A,MATCH(D11,Log!$G:$G,0))&"",INDEX(Log!$I:$I,MATCH(D11,Log!$G:$G,0))&""),IF(AND(LEN(D11)=4,LEFT(D11,1)="L",ISNUMBER(VALUE(MID(D11,2,3)))),"ID não encontrado no Log",""))) -> Perguntas enviadas com prazo até 29/09/2026, às 18h | J11: EXEMPLO — exclua esta linha
I12: =IF(D12="","",IFERROR(IF(INDEX(Log!$I:$I,MATCH(D12,Log!$G:$G,0))&""="",INDEX(Log!$A:$A,MATCH(D12,Log!$G:$G,0))&"",INDEX(Log!$I:$I,MATCH(D12,Log!$G:$G,0))&""),IF(AND(LEN(D12)=4,LEFT(D12,1)="L",ISNUMBER(VALUE(MID(D12,2,3)))),"ID não encontrado no Log","")))
I13: =IF(D13="","",IFERROR(IF(INDEX(Log!$I:$I,MATCH(D13,Log!$G:$G,0))&""="",INDEX(Log!$A:$A,MATCH(D13,Log!$G:$G,0))&"",INDEX(Log!$I:$I,MATCH(D13,Log!$G:$G,0))&""),IF(AND(LEN(D13)=4,LEFT(D13,1)="L",ISNUMBER(VALUE(MID(D13,2,3)))),"ID não encontrado no Log","")))
I14: =IF(D14="","",IFERROR(IF(INDEX(Log!$I:$I,MATCH(D14,Log!$G:$G,0))&""="",INDEX(Log!$A:$A,MATCH(D14,Log!$G:$G,0))&"",INDEX(Log!$I:$I,MATCH(D14,Log!$G:$G,0))&""),IF(AND(LEN(D14)=4,LEFT(D14,1)="L",ISNUMBER(VALUE(MID(D14,2,3)))),"ID não encontrado no Log","")))
I15: =IF(D15="","",IFERROR(IF(INDEX(Log!$I:$I,MATCH(D15,Log!$G:$G,0))&""="",INDEX(Log!$A:$A,MATCH(D15,Log!$G:$G,0))&"",INDEX(Log!$I:$I,MATCH(D15,Log!$G:$G,0))&""),IF(AND(LEN(D15)=4,LEFT(D15,1)="L",ISNUMBER(VALUE(MID(D15,2,3)))),"ID não encontrado no Log","")))
I16: =IF(D16="","",IFERROR(IF(INDEX(Log!$I:$I,MATCH(D16,Log!$G:$G,0))&""="",INDEX(Log!$A:$A,MATCH(D16,Log!$G:$G,0))&"",INDEX(Log!$I:$I,MATCH(D16,Log!$G:$G,0))&""),IF(AND(LEN(D16)=4,LEFT(D16,1)="L",ISNUMBER(VALUE(MID(D16,2,3)))),"ID não encontrado no Log","")))
I17: =IF(D17="","",IFERROR(IF(INDEX(Log!$I:$I,MATCH(D17,Log!$G:$G,0))&""="",INDEX(Log!$A:$A,MATCH(D17,Log!$G:$G,0))&"",INDEX(Log!$I:$I,MATCH(D17,Log!$G:$G,0))&""),IF(AND(LEN(D17)=4,LEFT(D17,1)="L",ISNUMBER(VALUE(MID(D17,2,3)))),"ID não encontrado no Log","")))
I18: =IF(D18="","",IFERROR(IF(INDEX(Log!$I:$I,MATCH(D18,Log!$G:$G,0))&""="",INDEX(Log!$A:$A,MATCH(D18,Log!$G:$G,0))&"",INDEX(Log!$I:$I,MATCH(D18,Log!$G:$G,0))&""),IF(AND(LEN(D18)=4,LEFT(D18,1)="L",ISNUMBER(VALUE(MID(D18,2,3)))),"ID não encontrado no Log","")))
I19: =IF(D19="","",IFERROR(IF(INDEX(Log!$I:$I,MATCH(D19,Log!$G:$G,0))&""="",INDEX(Log!$A:$A,MATCH(D19,Log!$G:$G,0))&"",INDEX(Log!$I:$I,MATCH(D19,Log!$G:$G,0))&""),IF(AND(LEN(D19)=4,LEFT(D19,1)="L",ISNUMBER(VALUE(MID(D19,2,3)))),"ID não encontrado no Log","")))
I20: =IF(D20="","",IFERROR(IF(INDEX(Log!$I:$I,MATCH(D20,Log!$G:$G,0))&""="",INDEX(Log!$A:$A,MATCH(D20,Log!$G:$G,0))&"",INDEX(Log!$I:$I,MATCH(D20,Log!$G:$G,0))&""),IF(AND(LEN(D20)=4,LEFT(D20,1)="L",ISNUMBER(VALUE(MID(D20,2,3)))),"ID não encontrado no Log","")))
I21: =IF(D21="","",IFERROR(IF(INDEX(Log!$I:$I,MATCH(D21,Log!$G:$G,0))&""="",INDEX(Log!$A:$A,MATCH(D21,Log!$G:$G,0))&"",INDEX(Log!$I:$I,MATCH(D21,Log!$G:$G,0))&""),IF(AND(LEN(D21)=4,LEFT(D21,1)="L",ISNUMBER(VALUE(MID(D21,2,3)))),"ID não encontrado no Log","")))
I22: =IF(D22="","",IFERROR(IF(INDEX(Log!$I:$I,MATCH(D22,Log!$G:$G,0))&""="",INDEX(Log!$A:$A,MATCH(D22,Log!$G:$G,0))&"",INDEX(Log!$I:$I,MATCH(D22,Log!$G:$G,0))&""),IF(AND(LEN(D22)=4,LEFT(D22,1)="L",ISNUMBER(VALUE(MID(D22,2,3)))),"ID não encontrado no Log","")))
I23: =IF(D23="","",IFERROR(IF(INDEX(Log!$I:$I,MATCH(D23,Log!$G:$G,0))&""="",INDEX(Log!$A:$A,MATCH(D23,Log!$G:$G,0))&"",INDEX(Log!$I:$I,MATCH(D23,Log!$G:$G,0))&""),IF(AND(LEN(D23)=4,LEFT(D23,1)="L",ISNUMBER(VALUE(MID(D23,2,3)))),"ID não encontrado no Log","")))
... I501: =IF(D501="","",IFERROR(IF(INDEX(Log!$I:$I,MATCH(D501,Log!$G:$G,0))&""="",INDEX(Log!$A:$A,MATCH(D501,Log!$G:$G,0))&"",INDEX(Log!$I:$I,MATCH(D501,Log!$G:$G,0))&""),IF(AND(LEN(D501)=4,LEFT(D501,1)="L",ISNUMBER(VALUE(MID(D501,2,3)))),"ID não encontrado no Log","")))

Sheet Ética da pauta
A1: Item | B1: Em duas linhas | C1: Como vou lidar | D1: Observações
A2: Interesse público | B2: Dinheiro da merenda de Cidade Exemplo foi para uma empresa aberta cinco meses antes, contratada sem licitação. O mesmo caminho existe em qualquer prefeitura que compra por dispensa. | D2: EXEMPLO — apague o texto em itálico e escreva o seu
A3: Conflito de interesse | B3: Sem vínculo com a prefeitura, com a empresa ou com o vereador. | C3: Se surgir vínculo, declaro aqui ou passo a pauta adiante. | D3: EXEMPLO — apague o texto em itálico
A4: Quem não será exposto | B4: Sócia de fornecedora sem cargo público; merendeiras e alunos; servidores sem cargo de chefia. | C4: Aparecem só com tarja ou com autorização. | D4: EXEMPLO — apague o texto em itálico

Sheet Fontes
A1: Fonte | B1: Tipo | C1: Acesso | D1: Interesse | E1: Histórico | F1: Corroboração | G1: Ordem de abordagem | H1: Combinado | I1: Risco para a fonte | J1: Alerta (auto) | K1: Observações
A2: Merendeira de uma escola atendida | B2: Testemunha | C2: 3 | D2: 1 | F2: Cardápio e fotos das entregas | G2: 1 | H2: Off | I2: média | J2: =IF(A2="","",IF(AND(C2=3,D2=3,OR(F2="",F2=1,LOWER(F2&"")="não",LOWER(F2&"")="nenhuma")),"Muito acesso, muito interesse, sem corroboração: a mais perigosa (aula 2.1)","")) | K2: EXEMPLO — exclua esta linha
A3: Fornecedor concorrente que perdeu a disputa | B3: Gente do setor | C3: 2 | D3: 3 | E3: 1 | F3: Propostas da dispensa | G3: 2 | H3: Ainda não combinado | I3: baixa | J3: =IF(A3="","",IF(AND(C3=3,D3=3,OR(F3="",F3=1,LOWER(F3&"")="não",LOWER(F3&"")="nenhuma")),"Muito acesso, muito interesse, sem corroboração: a mais perigosa (aula 2.1)","")) | K3: EXEMPLO — exclua esta linha
A4: Vereador de oposição | B4: Adversário político | C4: 2 | D4: 3 | E4: 2 | G4: 3 | H4: On | I4: baixa | J4: =IF(A4="","",IF(AND(C4=3,D4=3,OR(F4="",F4=1,LOWER(F4&"")="não",LOWER(F4&"")="nenhuma")),"Muito acesso, muito interesse, sem corroboração: a mais perigosa (aula 2.1)","")) | K4: EXEMPLO — ouça e desconfie na mesma medida
A5: F1 — servidor de carreira do setor de compras | B5: De dentro do órgão | C5: 3 | D5: 3 | E5: 1 | G5: 4 | H5: Off | I5: alta | J5: =IF(A5="","",IF(AND(C5=3,D5=3,OR(F5="",F5=1,LOWER(F5&"")="não",LOWER(F5&"")="nenhuma")),"Muito acesso, muito interesse, sem corroboração: a mais perigosa (aula 2.1)","")) -> Muito acesso, muito interesse, sem corroboração: a mais perigosa (aula 2.1) | K5: EXEMPLO — protocolo da aula 2.2 antes do primeiro contato
A6: Sócio-administrador da Alimentos Modelo | B6: Alvo | C6: 3 | D6: 3 | F6: Contrato, pagamentos e cadastro CNPJ | G6: 5 | H6: On | I6: baixa | J6: =IF(A6="","",IF(AND(C6=3,D6=3,OR(F6="",F6=1,LOWER(F6&"")="não",LOWER(F6&"")="nenhuma")),"Muito acesso, muito interesse, sem corroboração: a mais perigosa (aula 2.1)","")) | K6: EXEMPLO — o centro fica por último, quando você já sabe o que perguntar
J7: =IF(A7="","",IF(AND(C7=3,D7=3,OR(F7="",F7=1,LOWER(F7&"")="não",LOWER(F7&"")="nenhuma")),"Muito acesso, muito interesse, sem corroboração: a mais perigosa (aula 2.1)",""))
J8: =IF(A8="","",IF(AND(C8=3,D8=3,OR(F8="",F8=1,LOWER(F8&"")="não",LOWER(F8&"")="nenhuma")),"Muito acesso, muito interesse, sem corroboração: a mais perigosa (aula 2.1)",""))
J9: =IF(A9="","",IF(AND(C9=3,D9=3,OR(F9="",F9=1,LOWER(F9&"")="não",LOWER(F9&"")="nenhuma")),"Muito acesso, muito interesse, sem corroboração: a mais perigosa (aula 2.1)",""))
J10: =IF(A10="","",IF(AND(C10=3,D10=3,OR(F10="",F10=1,LOWER(F10&"")="não",LOWER(F10&"")="nenhuma")),"Muito acesso, muito interesse, sem corroboração: a mais perigosa (aula 2.1)",""))
J11: =IF(A11="","",IF(AND(C11=3,D11=3,OR(F11="",F11=1,LOWER(F11&"")="não",LOWER(F11&"")="nenhuma")),"Muito acesso, muito interesse, sem corroboração: a mais perigosa (aula 2.1)",""))
J12: =IF(A12="","",IF(AND(C12=3,D12=3,OR(F12="",F12=1,LOWER(F12&"")="não",LOWER(F12&"")="nenhuma")),"Muito acesso, muito interesse, sem corroboração: a mais perigosa (aula 2.1)",""))
J13: =IF(A13="","",IF(AND(C13=3,D13=3,OR(F13="",F13=1,LOWER(F13&"")="não",LOWER(F13&"")="nenhuma")),"Muito acesso, muito interesse, sem corroboração: a mais perigosa (aula 2.1)",""))
J14: =IF(A14="","",IF(AND(C14=3,D14=3,OR(F14="",F14=1,LOWER(F14&"")="não",LOWER(F14&"")="nenhuma")),"Muito acesso, muito interesse, sem corroboração: a mais perigosa (aula 2.1)",""))
J15: =IF(A15="","",IF(AND(C15=3,D15=3,OR(F15="",F15=1,LOWER(F15&"")="não",LOWER(F15&"")="nenhuma")),"Muito acesso, muito interesse, sem corroboração: a mais perigosa (aula 2.1)",""))
J16: =IF(A16="","",IF(AND(C16=3,D16=3,OR(F16="",F16=1,LOWER(F16&"")="não",LOWER(F16&"")="nenhuma")),"Muito acesso, muito interesse, sem corroboração: a mais perigosa (aula 2.1)",""))
J17: =IF(A17="","",IF(AND(C17=3,D17=3,OR(F17="",F17=1,LOWER(F17&"")="não",LOWER(F17&"")="nenhuma")),"Muito acesso, muito interesse, sem corroboração: a mais perigosa (aula 2.1)",""))
J18: =IF(A18="","",IF(AND(C18=3,D18=3,OR(F18="",F18=1,LOWER(F18&"")="não",LOWER(F18&"")="nenhuma")),"Muito acesso, muito interesse, sem corroboração: a mais perigosa (aula 2.1)",""))
... J51: =IF(A51="","",IF(AND(C51=3,D51=3,OR(F51="",F51=1,LOWER(F51&"")="não",LOWER(F51&"")="nenhuma")),"Muito acesso, muito interesse, sem corroboração: a mais perigosa (aula 2.1)",""))

Sheet Log
A1: Origem | B1: Data e hora | C1: Ferramenta | D1: Arquivo | E1: Código ou protocolo | F1: Hash SHA-256 | G1: ID | H1: Tipo | I1: Descrição | J1: Cópia arquivada | K1: Citado na Linha do tempo (auto) | L1: Alertas (auto) | M1: Observações
A2: https://minhareceita.org | B2: 46266.425 | C2: Minha Receita | D2: cnpj-empresas-da-pauta.json | F2: aaa3e37cae511b0b47a83f21815efd0f8f6fb2b73bf42c43eaaccda59a7cb22d | G2: L001 | H2: Base de dados | I2: Cadastro CNPJ e quadro de sócios da Alimentos Modelo, da Construtora Exemplo e da Gráfica Exemplo | K2: =IF(G2="","",COUNTIF('Linha do tempo'!$D:$D,G2)) -> 1 | L2: =IF(AND(G2="",F2=""),"",TRIM(IF(AND(G2<>"",COUNTIF($G:$G,G2)>1),"ID repetido. ","")&IF(AND(F2<>"",LEN(TRIM(F2))<>64),"Hash deve ter 64 caracteres.",""))) | M2: EXEMPLO — exclua esta linha
A3: Diário oficial da Câmara de Cidade Exemplo | B3: 46266.479 | C3: Navegador | D3: nomeacao-2025-01-15.pdf | F3: bfd323af355e2847ce1eb8b7394cbca20bd538632a64786095e032b35f655862 | G3: L002 | H3: Documento público baixado | I3: Ato de nomeação de Fulano de Tal (15/01/2025) | K3: =IF(G3="","",COUNTIF('Linha do tempo'!$D:$D,G3)) -> 1 | L3: =IF(AND(G3="",F3=""),"",TRIM(IF(AND(G3<>"",COUNTIF($G:$G,G3)>1),"ID repetido. ","")&IF(AND(F3<>"",LEN(TRIM(F3))<>64),"Hash deve ter 64 caracteres.",""))) | M3: EXEMPLO — exclua esta linha
A4: https://pncp.gov.br | B4: 46267.403 | C4: Navegador | D4: contratos-045-2025-e-008-2025.pdf | F4: 7dfb629af7bdb7d70391564cd53257273e071918e2c46294c171073eabfc3e48 | G4: L003 | H4: Documento público baixado | I4: Extratos dos contratos 045/2025 (dispensa) e 008/2025 (pregão) | K4: =IF(G4="","",COUNTIF('Linha do tempo'!$D:$D,G4)) -> 2 | L4: =IF(AND(G4="",F4=""),"",TRIM(IF(AND(G4<>"",COUNTIF($G:$G,G4)>1),"ID repetido. ","")&IF(AND(F4<>"",LEN(TRIM(F4))<>64),"Hash deve ter 64 caracteres.",""))) | M4: EXEMPLO — exclua esta linha
A5: Portal da transparência de Cidade Exemplo | B5: 46267.42 | C5: Exportação em CSV | D5: pagamentos-2023-2025.csv | F5: 822c83d154a336001c9656b0da07d2d8695f9b315175af880fb62cd88809585c | G5: L004 | H5: Base de dados | I5: Empenhos e pagamentos a fornecedores, de 2023 a 2025 | K5: =IF(G5="","",COUNTIF('Linha do tempo'!$D:$D,G5)) -> 1 | L5: =IF(AND(G5="",F5=""),"",TRIM(IF(AND(G5<>"",COUNTIF($G:$G,G5)>1),"ID repetido. ","")&IF(AND(F5<>"",LEN(TRIM(F5))<>64),"Hash deve ter 64 caracteres.",""))) | M5: EXEMPLO — exclua esta linha
A6: https://portaldatransparencia.gov.br | B6: 46267.438 | C6: Consulta CEIS, CNEP e CEPIM | D6: sancoes-2026-09-02.pdf | F6: 68ac4fae8b3bece5b4b82d1815c02c213b602c2f93dd55b4874136724bfb5bf6 | G6: L005 | H6: Base de dados | I6: Construtora Exemplo no CEIS; Alimentos Modelo e Gráfica Exemplo: não consta | K6: =IF(G6="","",COUNTIF('Linha do tempo'!$D:$D,G6)) -> 0 | L6: =IF(AND(G6="",F6=""),"",TRIM(IF(AND(G6<>"",COUNTIF($G:$G,G6)>1),"ID repetido. ","")&IF(AND(F6<>"",LEN(TRIM(F6))<>64),"Hash deve ter 64 caracteres.",""))) | M6: EXEMPLO — exclua esta linha
A7: https://divulgacandcontas.tse.jus.br | B7: 46268.385 | C7: Navegador | D7: tse-sicrano-2024-2026.pdf | F7: 79a23d3eed159a1ef385b48a15099aad7823727f92ef85d1d2a5f58058c41de7 | G7: L006 | H7: Base de dados | I7: Bens, doadores e fornecedores de campanha de Sicrano Candidato (2024 e 2026) | K7: =IF(G7="","",COUNTIF('Linha do tempo'!$D:$D,G7)) -> 2 | L7: =IF(AND(G7="",F7=""),"",TRIM(IF(AND(G7<>"",COUNTIF($G:$G,G7)>1),"ID repetido. ","")&IF(AND(F7<>"",LEN(TRIM(F7))<>64),"Hash deve ter 64 caracteres.",""))) | M7: EXEMPLO — exclua esta linha
A8: Tribunal de Justiça — consulta processual | B8: 46268.597 | C8: Navegador | D8: decisao-recebimento.pdf | E8: 0000001-00.2026.8.99.0001 | F8: f27cd310c476f7a46c3647a5021e236d20c6905a39c134e8f17de1ad7c16f42c | G8: L007 | H8: Documento público baixado | I8: Decisão que recebeu a ação de improbidade | K8: =IF(G8="","",COUNTIF('Linha do tempo'!$D:$D,G8)) -> 1 | L8: =IF(AND(G8="",F8=""),"",TRIM(IF(AND(G8<>"",COUNTIF($G:$G,G8)>1),"ID repetido. ","")&IF(AND(F8<>"",LEN(TRIM(F8))<>64),"Hash deve ter 64 caracteres.",""))) | M8: EXEMPLO — exclua esta linha
A9: FNDE | B9: 46267.667 | C9: Sistema federal de pedidos | D9: pedido-fnde.pdf | E9: 99999.000001/2026-00 | G9: L008 | H9: Pedido LAI | I9: Repasses do PNAE a Cidade Exemplo em 2025, por mês | K9: =IF(G9="","",COUNTIF('Linha do tempo'!$D:$D,G9)) -> 0 | L9: =IF(AND(G9="",F9=""),"",TRIM(IF(AND(G9<>"",COUNTIF($G:$G,G9)>1),"ID repetido. ","")&IF(AND(F9<>"",LEN(TRIM(F9))<>64),"Hash deve ter 64 caracteres.",""))) | M9: EXEMPLO — exclua esta linha
A10: Prefeitura de Cidade Exemplo | B10: 46254.632 | C10: e-SIC municipal | D10: pedido-dispensa.pdf | E10: 99999.000002/2026-00 | G10: L009 | H10: Pedido LAI | I10: Processo completo da dispensa 045/2025 | K10: =IF(G10="","",COUNTIF('Linha do tempo'!$D:$D,G10)) -> 0 | L10: =IF(AND(G10="",F10=""),"",TRIM(IF(AND(G10<>"",COUNTIF($G:$G,G10)>1),"ID repetido. ","")&IF(AND(F10<>"",LEN(TRIM(F10))<>64),"Hash deve ter 64 caracteres.",""))) | M10: EXEMPLO — exclua esta linha
A11: Prefeitura de Cidade Exemplo | B11: 46283.74 | C11: e-SIC municipal | D11: resposta-dispensa.pdf | E11: 99999.000002/2026-00 | F11: 25ec1104eec583935e92060e29ffc342e6d78fe540d75ff4a6723cbdfa9b0e0a | G11: L010 | H11: Resposta de órgão | I11: Resposta parcial: faltou a pesquisa de preços | K11: =IF(G11="","",COUNTIF('Linha do tempo'!$D:$D,G11)) -> 0 | L11: =IF(AND(G11="",F11=""),"",TRIM(IF(AND(G11<>"",COUNTIF($G:$G,G11)>1),"ID repetido. ","")&IF(AND(F11<>"",LEN(TRIM(F11))<>64),"Hash deve ter 64 caracteres.",""))) | M11: EXEMPLO — exclua esta linha
A12: F1 | B12: 46270.792 | C12: Signal | G12: L011 | H12: Entrevista ou conversa | I12: Conversa em off com F1 sobre a contratação da merenda | K12: =IF(G12="","",COUNTIF('Linha do tempo'!$D:$D,G12)) -> 1 | L12: =IF(AND(G12="",F12=""),"",TRIM(IF(AND(G12<>"",COUNTIF($G:$G,G12)>1),"ID repetido. ","")&IF(AND(F12<>"",LEN(TRIM(F12))<>64),"Hash deve ter 64 caracteres.",""))) | M12: EXEMPLO — fonte humana só pelo código
A13: Alimentos Modelo; gabinete de Sicrano Candidato; Câmara Municipal | B13: 46289.417 | C13: E-mail da pauta | D13: posicionamento-2026-09-24.pdf | F13: 349f0c3a08e2f88754adfc42972c8b0dfe9100b90f5d175ae4a3d41b746a25bb | G13: L012 | H13: Pedido de posicionamento | I13: Perguntas enviadas com prazo até 29/09/2026, às 18h | K13: =IF(G13="","",COUNTIF('Linha do tempo'!$D:$D,G13)) -> 1 | L13: =IF(AND(G13="",F13=""),"",TRIM(IF(AND(G13<>"",COUNTIF($G:$G,G13)>1),"ID repetido. ","")&IF(AND(F13<>"",LEN(TRIM(F13))<>64),"Hash deve ter 64 caracteres.",""))) | M13: EXEMPLO — exclua esta linha
A14: https://pncp.gov.br | B14: 46269.389 | C14: Navegador | D14: contrato-012-2023.pdf | F14: c45b173470e3c72ba90a82e3e2766dfe9a7f273d6ff256b455743dd157c200fb | G14: L013 | H14: Documento público baixado | I14: Extrato do contrato 012/2023 (Construtora Exemplo) | K14: =IF(G14="","",COUNTIF('Linha do tempo'!$D:$D,G14)) -> 0 | L14: =IF(AND(G14="",F14=""),"",TRIM(IF(AND(G14<>"",COUNTIF($G:$G,G14)>1),"ID repetido. ","")&IF(AND(F14<>"",LEN(TRIM(F14))<>64),"Hash deve ter 64 caracteres.",""))) | M14: EXEMPLO — exclua esta linha
A15: Portal da transparência de Cidade Exemplo, página de despesas | B15: 46269.417 | C15: Wayback e SingleFile | D15: despesas-2025.html | F15: c4817b1a158db7615d452955cd88d428a3ab04b2372bed7fff52ce955aca48cc | G15: L014 | H15: Página arquivada | I15: Página de despesas de 2025, arquivada em dois lugares | J15: https://web.archive.org/web/20260904100000/https://transparencia.cidadeexemplo.gov.br/despesas | K15: =IF(G15="","",COUNTIF('Linha do tempo'!$D:$D,G15)) -> 0 | L15: =IF(AND(G15="",F15=""),"",TRIM(IF(AND(G15<>"",COUNTIF($G:$G,G15)>1),"ID repetido. ","")&IF(AND(F15<>"",LEN(TRIM(F15))<>64),"Hash deve ter 64 caracteres.",""))) | M15: EXEMPLO — exclua esta linha
A16: Tribunal de Contas do Estado — pesquisa de processos | B16: 46275.458 | C16: Navegador | D16: relatorio-tce.pdf | E16: TC-0000/2026 | F16: d485a210907cd3156822ca520351a39a2ba5b7dba1e5c6978e08464078e7a2e1 | G16: L015 | H16: Documento público baixado | I16: Relatório da área técnica na representação sobre a dispensa 045/2025 | K16: =IF(G16="","",COUNTIF('Linha do tempo'!$D:$D,G16)) -> 0 | L16: =IF(AND(G16="",F16=""),"",TRIM(IF(AND(G16<>"",COUNTIF($G:$G,G16)>1),"ID repetido. ","")&IF(AND(F16<>"",LEN(TRIM(F16))<>64),"Hash deve ter 64 caracteres.",""))) | M16: EXEMPLO — exclua esta linha
A17: Perfis de Sicrano Candidato e da prefeitura | B17: 46276.646 | C17: Wayback | D17: posts-merenda-2025.pdf | F17: 2395eb89c89c59080c916955d51587ae3c6a7fbf25ba075b369e9449b7d2b200 | G17: L016 | H17: Página arquivada | I17: Posts sobre a merenda publicados em 2025, arquivados | K17: =IF(G17="","",COUNTIF('Linha do tempo'!$D:$D,G17)) -> 0 | L17: =IF(AND(G17="",F17=""),"",TRIM(IF(AND(G17<>"",COUNTIF($G:$G,G17)>1),"ID repetido. ","")&IF(AND(F17<>"",LEN(TRIM(F17))<>64),"Hash deve ter 64 caracteres.",""))) | M17: EXEMPLO — exclua esta linha
K18: =IF(G18="","",COUNTIF('Linha do tempo'!$D:$D,G18)) | L18: =IF(AND(G18="",F18=""),"",TRIM(IF(AND(G18<>"",COUNTIF($G:$G,G18)>1),"ID repetido. ","")&IF(AND(F18<>"",LEN(TRIM(F18))<>64),"Hash deve ter 64 caracteres.","")))
K19: =IF(G19="","",COUNTIF('Linha do tempo'!$D:$D,G19)) | L19: =IF(AND(G19="",F19=""),"",TRIM(IF(AND(G19<>"",COUNTIF($G:$G,G19)>1),"ID repetido. ","")&IF(AND(F19<>"",LEN(TRIM(F19))<>64),"Hash deve ter 64 caracteres.","")))
K20: =IF(G20="","",COUNTIF('Linha do tempo'!$D:$D,G20)) | L20: =IF(AND(G20="",F20=""),"",TRIM(IF(AND(G20<>"",COUNTIF($G:$G,G20)>1),"ID repetido. ","")&IF(AND(F20<>"",LEN(TRIM(F20))<>64),"Hash deve ter 64 caracteres.","")))
K21: =IF(G21="","",COUNTIF('Linha do tempo'!$D:$D,G21)) | L21: =IF(AND(G21="",F21=""),"",TRIM(IF(AND(G21<>"",COUNTIF($G:$G,G21)>1),"ID repetido. ","")&IF(AND(F21<>"",LEN(TRIM(F21))<>64),"Hash deve ter 64 caracteres.","")))
K22: =IF(G22="","",COUNTIF('Linha do tempo'!$D:$D,G22)) | L22: =IF(AND(G22="",F22=""),"",TRIM(IF(AND(G22<>"",COUNTIF($G:$G,G22)>1),"ID repetido. ","")&IF(AND(F22<>"",LEN(TRIM(F22))<>64),"Hash deve ter 64 caracteres.","")))
K23: =IF(G23="","",COUNTIF('Linha do tempo'!$D:$D,G23)) | L23: =IF(AND(G23="",F23=""),"",TRIM(IF(AND(G23<>"",COUNTIF($G:$G,G23)>1),"ID repetido. ","")&IF(AND(F23<>"",LEN(TRIM(F23))<>64),"Hash deve ter 64 caracteres.","")))
K24: =IF(G24="","",COUNTIF('Linha do tempo'!$D:$D,G24)) | L24: =IF(AND(G24="",F24=""),"",TRIM(IF(AND(G24<>"",COUNTIF($G:$G,G24)>1),"ID repetido. ","")&IF(AND(F24<>"",LEN(TRIM(F24))<>64),"Hash deve ter 64 caracteres.","")))
K25: =IF(G25="","",COUNTIF('Linha do tempo'!$D:$D,G25)) | L25: =IF(AND(G25="",F25=""),"",TRIM(IF(AND(G25<>"",COUNTIF($G:$G,G25)>1),"ID repetido. ","")&IF(AND(F25<>"",LEN(TRIM(F25))<>64),"Hash deve ter 64 caracteres.","")))
K26: =IF(G26="","",COUNTIF('Linha do tempo'!$D:$D,G26)) | L26: =IF(AND(G26="",F26=""),"",TRIM(IF(AND(G26<>"",COUNTIF($G:$G,G26)>1),"ID repetido. ","")&IF(AND(F26<>"",LEN(TRIM(F26))<>64),"Hash deve ter 64 caracteres.","")))
K27: =IF(G27="","",COUNTIF('Linha do tempo'!$D:$D,G27)) | L27: =IF(AND(G27="",F27=""),"",TRIM(IF(AND(G27<>"",COUNTIF($G:$G,G27)>1),"ID repetido. ","")&IF(AND(F27<>"",LEN(TRIM(F27))<>64),"Hash deve ter 64 caracteres.","")))
K28: =IF(G28="","",COUNTIF('Linha do tempo'!$D:$D,G28)) | L28: =IF(AND(G28="",F28=""),"",TRIM(IF(AND(G28<>"",COUNTIF($G:$G,G28)>1),"ID repetido. ","")&IF(AND(F28<>"",LEN(TRIM(F28))<>64),"Hash deve ter 64 caracteres.","")))
K29: =IF(G29="","",COUNTIF('Linha do tempo'!$D:$D,G29)) | L29: =IF(AND(G29="",F29=""),"",TRIM(IF(AND(G29<>"",COUNTIF($G:$G,G29)>1),"ID repetido. ","")&IF(AND(F29<>"",LEN(TRIM(F29))<>64),"Hash deve ter 64 caracteres.","")))
... K501: =IF(G501="","",COUNTIF('Linha do tempo'!$D:$D,G501)) | L501: =IF(AND(G501="",F501=""),"",TRIM(IF(AND(G501<>"",COUNTIF($G:$G,G501)>1),"ID repetido. ","")&IF(AND(F501<>"",LEN(TRIM(F501))<>64),"Hash deve ter 64 caracteres.","")))

Sheet Risco
A1: Risco | B1: Probabilidade | C1: Impacto | D1: Medida | E1: Prioridade (auto) | F1: De quem é o risco | G1: Observações
A2: Ataque on-line de apoiadores do vereador | B2: alta | C2: médio | D2: Arquivar tudo, não responder, registrar ocorrência se virar ameaça | E2: =IF(OR(B2="",C2=""),"",IF(IFERROR(MATCH(B2,Listas!$N$2:$N$4,0)*MATCH(C2,Listas!$O$2:$O$4,0),0)=0,"escolha na lista",IF(MATCH(B2,Listas!$N$2:$N$4,0)*MATCH(C2,Listas!$O$2:$O$4,0)>=6,"ALTA — medida antes de seguir",IF(MATCH(B2,Listas!$N$2:$N$4,0)*MATCH(C2,Listas!$O$2:$O$4,0)>=3,"MÉDIA","baixa")))) -> ALTA — medida antes de seguir | F2: Você | G2: EXEMPLO — exclua esta linha
A3: Processo de um dos citados | B3: média | C3: alto | D3: Dossiê, pedido de posicionamento, redação na medida da prova (módulos 5 e 6) | E3: =IF(OR(B3="",C3=""),"",IF(IFERROR(MATCH(B3,Listas!$N$2:$N$4,0)*MATCH(C3,Listas!$O$2:$O$4,0),0)=0,"escolha na lista",IF(MATCH(B3,Listas!$N$2:$N$4,0)*MATCH(C3,Listas!$O$2:$O$4,0)>=6,"ALTA — medida antes de seguir",IF(MATCH(B3,Listas!$N$2:$N$4,0)*MATCH(C3,Listas!$O$2:$O$4,0)>=3,"MÉDIA","baixa")))) -> ALTA — medida antes de seguir | F3: Você | G3: EXEMPLO — exclua esta linha
A4: Visita ao endereço da empresa | B4: baixa | C4: alto | D4: Não ir sozinho, avisar o roteiro, não postar em tempo real; ou ficar com Street View e documentos | E4: =IF(OR(B4="",C4=""),"",IF(IFERROR(MATCH(B4,Listas!$N$2:$N$4,0)*MATCH(C4,Listas!$O$2:$O$4,0),0)=0,"escolha na lista",IF(MATCH(B4,Listas!$N$2:$N$4,0)*MATCH(C4,Listas!$O$2:$O$4,0)>=6,"ALTA — medida antes de seguir",IF(MATCH(B4,Listas!$N$2:$N$4,0)*MATCH(C4,Listas!$O$2:$O$4,0)>=3,"MÉDIA","baixa")))) -> MÉDIA | F4: Você | G4: EXEMPLO — exclua esta linha
A5: Exposição da fonte F1 | B5: média | C5: alto | D5: Protocolo da aula 2.2 | E5: =IF(OR(B5="",C5=""),"",IF(IFERROR(MATCH(B5,Listas!$N$2:$N$4,0)*MATCH(C5,Listas!$O$2:$O$4,0),0)=0,"escolha na lista",IF(MATCH(B5,Listas!$N$2:$N$4,0)*MATCH(C5,Listas!$O$2:$O$4,0)>=6,"ALTA — medida antes de seguir",IF(MATCH(B5,Listas!$N$2:$N$4,0)*MATCH(C5,Listas!$O$2:$O$4,0)>=3,"MÉDIA","baixa")))) -> ALTA — medida antes de seguir | F5: A fonte | G5: EXEMPLO — exclua esta linha
A6: Conta de e-mail ou de rede invadida | B6: média | C6: alto | D6: Verificação em duas etapas por aplicativo, hoje; gerenciador de senhas; disco criptografado | E6: =IF(OR(B6="",C6=""),"",IF(IFERROR(MATCH(B6,Listas!$N$2:$N$4,0)*MATCH(C6,Listas!$O$2:$O$4,0),0)=0,"escolha na lista",IF(MATCH(B6,Listas!$N$2:$N$4,0)*MATCH(C6,Listas!$O$2:$O$4,0)>=6,"ALTA — medida antes de seguir",IF(MATCH(B6,Listas!$N$2:$N$4,0)*MATCH(C6,Listas!$O$2:$O$4,0)>=3,"MÉDIA","baixa")))) -> ALTA — medida antes de seguir | F6: Você | G6: EXEMPLO — exclua esta linha
E7: =IF(OR(B7="",C7=""),"",IF(IFERROR(MATCH(B7,Listas!$N$2:$N$4,0)*MATCH(C7,Listas!$O$2:$O$4,0),0)=0,"escolha na lista",IF(MATCH(B7,Listas!$N$2:$N$4,0)*MATCH(C7,Listas!$O$2:$O$4,0)>=6,"ALTA — medida antes de seguir",IF(MATCH(B7,Listas!$N$2:$N$4,0)*MATCH(C7,Listas!$O$2:$O$4,0)>=3,"MÉDIA","baixa"))))
E8: =IF(OR(B8="",C8=""),"",IF(IFERROR(MATCH(B8,Listas!$N$2:$N$4,0)*MATCH(C8,Listas!$O$2:$O$4,0),0)=0,"escolha na lista",IF(MATCH(B8,Listas!$N$2:$N$4,0)*MATCH(C8,Listas!$O$2:$O$4,0)>=6,"ALTA — medida antes de seguir",IF(MATCH(B8,Listas!$N$2:$N$4,0)*MATCH(C8,Listas!$O$2:$O$4,0)>=3,"MÉDIA","baixa"))))
E9: =IF(OR(B9="",C9=""),"",IF(IFERROR(MATCH(B9,Listas!$N$2:$N$4,0)*MATCH(C9,Listas!$O$2:$O$4,0),0)=0,"escolha na lista",IF(MATCH(B9,Listas!$N$2:$N$4,0)*MATCH(C9,Listas!$O$2:$O$4,0)>=6,"ALTA — medida antes de seguir",IF(MATCH(B9,Listas!$N$2:$N$4,0)*MATCH(C9,Listas!$O$2:$O$4,0)>=3,"MÉDIA","baixa"))))
E10: =IF(OR(B10="",C10=""),"",IF(IFERROR(MATCH(B10,Listas!$N$2:$N$4,0)*MATCH(C10,Listas!$O$2:$O$4,0),0)=0,"escolha na lista",IF(MATCH(B10,Listas!$N$2:$N$4,0)*MATCH(C10,Listas!$O$2:$O$4,0)>=6,"ALTA — medida antes de seguir",IF(MATCH(B10,Listas!$N$2:$N$4,0)*MATCH(C10,Listas!$O$2:$O$4,0)>=3,"MÉDIA","baixa"))))
E11: =IF(OR(B11="",C11=""),"",IF(IFERROR(MATCH(B11,Listas!$N$2:$N$4,0)*MATCH(C11,Listas!$O$2:$O$4,0),0)=0,"escolha na lista",IF(MATCH(B11,Listas!$N$2:$N$4,0)*MATCH(C11,Listas!$O$2:$O$4,0)>=6,"ALTA — medida antes de seguir",IF(MATCH(B11,Listas!$N$2:$N$4,0)*MATCH(C11,Listas!$O$2:$O$4,0)>=3,"MÉDIA","baixa"))))
E12: =IF(OR(B12="",C12=""),"",IF(IFERROR(MATCH(B12,Listas!$N$2:$N$4,0)*MATCH(C12,Listas!$O$2:$O$4,0),0)=0,"escolha na lista",IF(MATCH(B12,Listas!$N$2:$N$4,0)*MATCH(C12,Listas!$O$2:$O$4,0)>=6,"ALTA — medida antes de seguir",IF(MATCH(B12,Listas!$N$2:$N$4,0)*MATCH(C12,Listas!$O$2:$O$4,0)>=3,"MÉDIA","baixa"))))
E13: =IF(OR(B13="",C13=""),"",IF(IFERROR(MATCH(B13,Listas!$N$2:$N$4,0)*MATCH(C13,Listas!$O$2:$O$4,0),0)=0,"escolha na lista",IF(MATCH(B13,Listas!$N$2:$N$4,0)*MATCH(C13,Listas!$O$2:$O$4,0)>=6,"ALTA — medida antes de seguir",IF(MATCH(B13,Listas!$N$2:$N$4,0)*MATCH(C13,Listas!$O$2:$O$4,0)>=3,"MÉDIA","baixa"))))
E14: =IF(OR(B14="",C14=""),"",IF(IFERROR(MATCH(B14,Listas!$N$2:$N$4,0)*MATCH(C14,Listas!$O$2:$O$4,0),0)=0,"escolha na lista",IF(MATCH(B14,Listas!$N$2:$N$4,0)*MATCH(C14,Listas!$O$2:$O$4,0)>=6,"ALTA — medida antes de seguir",IF(MATCH(B14,Listas!$N$2:$N$4,0)*MATCH(C14,Listas!$O$2:$O$4,0)>=3,"MÉDIA","baixa"))))
E15: =IF(OR(B15="",C15=""),"",IF(IFERROR(MATCH(B15,Listas!$N$2:$N$4,0)*MATCH(C15,Listas!$O$2:$O$4,0),0)=0,"escolha na lista",IF(MATCH(B15,Listas!$N$2:$N$4,0)*MATCH(C15,Listas!$O$2:$O$4,0)>=6,"ALTA — medida antes de seguir",IF(MATCH(B15,Listas!$N$2:$N$4,0)*MATCH(C15,Listas!$O$2:$O$4,0)>=3,"MÉDIA","baixa"))))
E16: =IF(OR(B16="",C16=""),"",IF(IFERROR(MATCH(B16,Listas!$N$2:$N$4,0)*MATCH(C16,Listas!$O$2:$O$4,0),0)=0,"escolha na lista",IF(MATCH(B16,Listas!$N$2:$N$4,0)*MATCH(C16,Listas!$O$2:$O$4,0)>=6,"ALTA — medida antes de seguir",IF(MATCH(B16,Listas!$N$2:$N$4,0)*MATCH(C16,Listas!$O$2:$O$4,0)>=3,"MÉDIA","baixa"))))
E17: =IF(OR(B17="",C17=""),"",IF(IFERROR(MATCH(B17,Listas!$N$2:$N$4,0)*MATCH(C17,Listas!$O$2:$O$4,0),0)=0,"escolha na lista",IF(MATCH(B17,Listas!$N$2:$N$4,0)*MATCH(C17,Listas!$O$2:$O$4,0)>=6,"ALTA — medida antes de seguir",IF(MATCH(B17,Listas!$N$2:$N$4,0)*MATCH(C17,Listas!$O$2:$O$4,0)>=3,"MÉDIA","baixa"))))
E18: =IF(OR(B18="",C18=""),"",IF(IFERROR(MATCH(B18,Listas!$N$2:$N$4,0)*MATCH(C18,Listas!$O$2:$O$4,0),0)=0,"escolha na lista",IF(MATCH(B18,Listas!$N$2:$N$4,0)*MATCH(C18,Listas!$O$2:$O$4,0)>=6,"ALTA — medida antes de seguir",IF(MATCH(B18,Listas!$N$2:$N$4,0)*MATCH(C18,Listas!$O$2:$O$4,0)>=3,"MÉDIA","baixa"))))
... E51: =IF(OR(B51="",C51=""),"",IF(IFERROR(MATCH(B51,Listas!$N$2:$N$4,0)*MATCH(C51,Listas!$O$2:$O$4,0),0)=0,"escolha na lista",IF(MATCH(B51,Listas!$N$2:$N$4,0)*MATCH(C51,Listas!$O$2:$O$4,0)>=6,"ALTA — medida antes de seguir",IF(MATCH(B51,Listas!$N$2:$N$4,0)*MATCH(C51,Listas!$O$2:$O$4,0)>=3,"MÉDIA","baixa"))))

Sheet Documentos
A1: Documento | B1: Quem tem | C1: Já está publicado? | D1: Onde | E1: Próximo passo (auto) | F1: Protocolo do pedido | G1: Observações
A2: Extrato do contrato 045/2025 | B2: Secretaria Municipal de Educação | C2: Sim | D2: PNCP | E2: =IF(C2="","",IF(C2="Sim","Baixe e registre no Log",IF(C2="Não","Peça pela LAI (aula 3.2) e anote em Prazos LAI",IF(C2="Em parte","Baixe o que está publicado e peça o resto pela LAI","Procure antes de pedir: pedir o que já está publicado é perder 20 dias")))) -> Baixe e registre no Log | G2: EXEMPLO — exclua esta linha
A3: Processo completo da dispensa 045/2025, com pesquisa de preços e parecer | B3: Secretaria Municipal de Educação | C3: Não | E3: =IF(C3="","",IF(C3="Sim","Baixe e registre no Log",IF(C3="Não","Peça pela LAI (aula 3.2) e anote em Prazos LAI",IF(C3="Em parte","Baixe o que está publicado e peça o resto pela LAI","Procure antes de pedir: pedir o que já está publicado é perder 20 dias")))) -> Peça pela LAI (aula 3.2) e anote em Prazos LAI | F3: 99999.000002/2026-00 | G3: EXEMPLO — exclua esta linha
A4: Notas fiscais e ordens bancárias dos pagamentos à Alimentos Modelo | B4: Prefeitura e Tribunal de Contas do Estado | C4: Em parte | D4: Portal da transparência municipal: só valores e datas | E4: =IF(C4="","",IF(C4="Sim","Baixe e registre no Log",IF(C4="Não","Peça pela LAI (aula 3.2) e anote em Prazos LAI",IF(C4="Em parte","Baixe o que está publicado e peça o resto pela LAI","Procure antes de pedir: pedir o que já está publicado é perder 20 dias")))) -> Baixe o que está publicado e peça o resto pela LAI | G4: EXEMPLO — exclua esta linha
A5: Repasses do PNAE a Cidade Exemplo em 2025, por mês | B5: FNDE | C5: Talvez | D5: Painel do FNDE? | E5: =IF(C5="","",IF(C5="Sim","Baixe e registre no Log",IF(C5="Não","Peça pela LAI (aula 3.2) e anote em Prazos LAI",IF(C5="Em parte","Baixe o que está publicado e peça o resto pela LAI","Procure antes de pedir: pedir o que já está publicado é perder 20 dias")))) -> Procure antes de pedir: pedir o que já está publicado é perder 20 dias | F5: 99999.000001/2026-00 | G5: EXEMPLO — exclua esta linha
A6: Decisão que recebeu a ação de improbidade | B6: Tribunal de Justiça | C6: Sim | D6: Consulta processual | E6: =IF(C6="","",IF(C6="Sim","Baixe e registre no Log",IF(C6="Não","Peça pela LAI (aula 3.2) e anote em Prazos LAI",IF(C6="Em parte","Baixe o que está publicado e peça o resto pela LAI","Procure antes de pedir: pedir o que já está publicado é perder 20 dias")))) -> Baixe e registre no Log | G6: EXEMPLO — exclua esta linha
E7: =IF(C7="","",IF(C7="Sim","Baixe e registre no Log",IF(C7="Não","Peça pela LAI (aula 3.2) e anote em Prazos LAI",IF(C7="Em parte","Baixe o que está publicado e peça o resto pela LAI","Procure antes de pedir: pedir o que já está publicado é perder 20 dias"))))
E8: =IF(C8="","",IF(C8="Sim","Baixe e registre no Log",IF(C8="Não","Peça pela LAI (aula 3.2) e anote em Prazos LAI",IF(C8="Em parte","Baixe o que está publicado e peça o resto pela LAI","Procure antes de pedir: pedir o que já está publicado é perder 20 dias"))))
E9: =IF(C9="","",IF(C9="Sim","Baixe e registre no Log",IF(C9="Não","Peça pela LAI (aula 3.2) e anote em Prazos LAI",IF(C9="Em parte","Baixe o que está publicado e peça o resto pela LAI","Procure antes de pedir: pedir o que já está publicado é perder 20 dias"))))
E10: =IF(C10="","",IF(C10="Sim","Baixe e registre no Log",IF(C10="Não","Peça pela LAI (aula 3.2) e anote em Prazos LAI",IF(C10="Em parte","Baixe o que está publicado e peça o resto pela LAI","Procure antes de pedir: pedir o que já está publicado é perder 20 dias"))))
E11: =IF(C11="","",IF(C11="Sim","Baixe e registre no Log",IF(C11="Não","Peça pela LAI (aula 3.2) e anote em Prazos LAI",IF(C11="Em parte","Baixe o que está publicado e peça o resto pela LAI","Procure antes de pedir: pedir o que já está publicado é perder 20 dias"))))
E12: =IF(C12="","",IF(C12="Sim","Baixe e registre no Log",IF(C12="Não","Peça pela LAI (aula 3.2) e anote em Prazos LAI",IF(C12="Em parte","Baixe o que está publicado e peça o resto pela LAI","Procure antes de pedir: pedir o que já está publicado é perder 20 dias"))))
E13: =IF(C13="","",IF(C13="Sim","Baixe e registre no Log",IF(C13="Não","Peça pela LAI (aula 3.2) e anote em Prazos LAI",IF(C13="Em parte","Baixe o que está publicado e peça o resto pela LAI","Procure antes de pedir: pedir o que já está publicado é perder 20 dias"))))
E14: =IF(C14="","",IF(C14="Sim","Baixe e registre no Log",IF(C14="Não","Peça pela LAI (aula 3.2) e anote em Prazos LAI",IF(C14="Em parte","Baixe o que está publicado e peça o resto pela LAI","Procure antes de pedir: pedir o que já está publicado é perder 20 dias"))))
E15: =IF(C15="","",IF(C15="Sim","Baixe e registre no Log",IF(C15="Não","Peça pela LAI (aula 3.2) e anote em Prazos LAI",IF(C15="Em parte","Baixe o que está publicado e peça o resto pela LAI","Procure antes de pedir: pedir o que já está publicado é perder 20 dias"))))
E16: =IF(C16="","",IF(C16="Sim","Baixe e registre no Log",IF(C16="Não","Peça pela LAI (aula 3.2) e anote em Prazos LAI",IF(C16="Em parte","Baixe o que está publicado e peça o resto pela LAI","Procure antes de pedir: pedir o que já está publicado é perder 20 dias"))))
E17: =IF(C17="","",IF(C17="Sim","Baixe e registre no Log",IF(C17="Não","Peça pela LAI (aula 3.2) e anote em Prazos LAI",IF(C17="Em parte","Baixe o que está publicado e peça o resto pela LAI","Procure antes de pedir: pedir o que já está publicado é perder 20 dias"))))
E18: =IF(C18="","",IF(C18="Sim","Baixe e registre no Log",IF(C18="Não","Peça pela LAI (aula 3.2) e anote em Prazos LAI",IF(C18="Em parte","Baixe o que está publicado e peça o resto pela LAI","Procure antes de pedir: pedir o que já está publicado é perder 20 dias"))))
... E101: =IF(C101="","",IF(C101="Sim","Baixe e registre no Log",IF(C101="Não","Peça pela LAI (aula 3.2) e anote em Prazos LAI",IF(C101="Em parte","Baixe o que está publicado e peça o resto pela LAI","Procure antes de pedir: pedir o que já está publicado é perder 20 dias"))))

Sheet Prazos LAI
A1: Protocolo | B1: Órgão | C1: Esfera | D1: O que foi pedido | E1: Data do pedido | F1: Prorrogado? | G1: Prazo de resposta (auto) | H1: Data da última resposta | I1: Resultado da última resposta | J1: Instância atual | K1: Data do último recurso ou reclamação | L1: Próxima data (auto) | M1: Dias até a próxima data (auto) | N1: Próxima ação (auto) | O1: Fonte (ID do Log) | P1: Observações
A2: 99999.000001/2026-00 | B2: FNDE | C2: Federal | D2: Repasses do PNAE a Cidade Exemplo em 2025, por mês | E2: 46267 | F2: Não | G2: =IF(E2="","",E2+IF(F2="Sim",30,20)) -> 46287 | J2: Pedido | L2: =IF(E2="","",IF(AND(K2<>"",OR(H2="",K2>=H2)),IF(J2="CMRI","",K2+5),IF(H2="",IF(TODAY()<=G2,G2,IF(TODAY()<E2+30,E2+30,E2+40)),IF(OR(I2="Negado",I2="Atendido em parte"),H2+10,"")))) -> 46297 | M2: =IF(L2="","",L2-TODAY()) -> 2 | N2: =IF(E2="","",IF(AND(K2<>"",OR(H2="",K2>=H2)),IF(J2="CMRI","Aguardar a CMRI (até a 3ª reunião mensal depois da autuação)","Aguardar decisão do recurso ou da reclamação"),IF(H2="",IF(TODAY()<=G2,"Aguardar resposta do órgão",IF(TODAY()<E2+30,"Prazo vencido: reclamação (modelo E) a partir da próxima data",IF(TODAY()<=E2+40,"Fazer reclamação (modelo E) até a próxima data","Janela de reclamação encerrada: novo pedido ou modelo G"))),IF(I2="Atendido","Concluído: registre a resposta no Log",IF(OR(I2="Negado",I2="Atendido em parte"),"Recorrer (modelo B ou D) até a próxima data","Preencha o resultado da resposta"))))) -> Prazo vencido: reclamação (modelo E) a partir da próxima data | O2: L008 | P2: EXEMPLO — exclua esta linha
A3: 99999.000002/2026-00 | B3: Prefeitura de Cidade Exemplo | C3: Municipal | D3: Processo completo da dispensa 045/2025 | E3: 46254 | F3: Sim | G3: =IF(E3="","",E3+IF(F3="Sim",30,20)) -> 46284 | H3: 46283 | I3: Atendido em parte | J3: Pedido | L3: =IF(E3="","",IF(AND(K3<>"",OR(H3="",K3>=H3)),IF(J3="CMRI","",K3+5),IF(H3="",IF(TODAY()<=G3,G3,IF(TODAY()<E3+30,E3+30,E3+40)),IF(OR(I3="Negado",I3="Atendido em parte"),H3+10,"")))) -> 46293 | M3: =IF(L3="","",L3-TODAY()) -> -2 | N3: =IF(E3="","",IF(AND(K3<>"",OR(H3="",K3>=H3)),IF(J3="CMRI","Aguardar a CMRI (até a 3ª reunião mensal depois da autuação)","Aguardar decisão do recurso ou da reclamação"),IF(H3="",IF(TODAY()<=G3,"Aguardar resposta do órgão",IF(TODAY()<E3+30,"Prazo vencido: reclamação (modelo E) a partir da próxima data",IF(TODAY()<=E3+40,"Fazer reclamação (modelo E) até a próxima data","Janela de reclamação encerrada: novo pedido ou modelo G"))),IF(I3="Atendido","Concluído: registre a resposta no Log",IF(OR(I3="Negado",I3="Atendido em parte"),"Recorrer (modelo B ou D) até a próxima data","Preencha o resultado da resposta"))))) -> Recorrer (modelo B ou D) até a próxima data | O3: L009 | P3: EXEMPLO — faltou a pesquisa de preços (L010)
G4: =IF(E4="","",E4+IF(F4="Sim",30,20)) | L4: =IF(E4="","",IF(AND(K4<>"",OR(H4="",K4>=H4)),IF(J4="CMRI","",K4+5),IF(H4="",IF(TODAY()<=G4,G4,IF(TODAY()<E4+30,E4+30,E4+40)),IF(OR(I4="Negado",I4="Atendido em parte"),H4+10,"")))) | M4: =IF(L4="","",L4-TODAY()) | N4: =IF(E4="","",IF(AND(K4<>"",OR(H4="",K4>=H4)),IF(J4="CMRI","Aguardar a CMRI (até a 3ª reunião mensal depois da autuação)","Aguardar decisão do recurso ou da reclamação"),IF(H4="",IF(TODAY()<=G4,"Aguardar resposta do órgão",IF(TODAY()<E4+30,"Prazo vencido: reclamação (modelo E) a partir da próxima data",IF(TODAY()<=E4+40,"Fazer reclamação (modelo E) até a próxima data","Janela de reclamação encerrada: novo pedido ou modelo G"))),IF(I4="Atendido","Concluído: registre a resposta no Log",IF(OR(I4="Negado",I4="Atendido em parte"),"Recorrer (modelo B ou D) até a próxima data","Preencha o resultado da resposta")))))
G5: =IF(E5="","",E5+IF(F5="Sim",30,20)) | L5: =IF(E5="","",IF(AND(K5<>"",OR(H5="",K5>=H5)),IF(J5="CMRI","",K5+5),IF(H5="",IF(TODAY()<=G5,G5,IF(TODAY()<E5+30,E5+30,E5+40)),IF(OR(I5="Negado",I5="Atendido em parte"),H5+10,"")))) | M5: =IF(L5="","",L5-TODAY()) | N5: =IF(E5="","",IF(AND(K5<>"",OR(H5="",K5>=H5)),IF(J5="CMRI","Aguardar a CMRI (até a 3ª reunião mensal depois da autuação)","Aguardar decisão do recurso ou da reclamação"),IF(H5="",IF(TODAY()<=G5,"Aguardar resposta do órgão",IF(TODAY()<E5+30,"Prazo vencido: reclamação (modelo E) a partir da próxima data",IF(TODAY()<=E5+40,"Fazer reclamação (modelo E) até a próxima data","Janela de reclamação encerrada: novo pedido ou modelo G"))),IF(I5="Atendido","Concluído: registre a resposta no Log",IF(OR(I5="Negado",I5="Atendido em parte"),"Recorrer (modelo B ou D) até a próxima data","Preencha o resultado da resposta")))))
G6: =IF(E6="","",E6+IF(F6="Sim",30,20)) | L6: =IF(E6="","",IF(AND(K6<>"",OR(H6="",K6>=H6)),IF(J6="CMRI","",K6+5),IF(H6="",IF(TODAY()<=G6,G6,IF(TODAY()<E6+30,E6+30,E6+40)),IF(OR(I6="Negado",I6="Atendido em parte"),H6+10,"")))) | M6: =IF(L6="","",L6-TODAY()) | N6: =IF(E6="","",IF(AND(K6<>"",OR(H6="",K6>=H6)),IF(J6="CMRI","Aguardar a CMRI (até a 3ª reunião mensal depois da autuação)","Aguardar decisão do recurso ou da reclamação"),IF(H6="",IF(TODAY()<=G6,"Aguardar resposta do órgão",IF(TODAY()<E6+30,"Prazo vencido: reclamação (modelo E) a partir da próxima data",IF(TODAY()<=E6+40,"Fazer reclamação (modelo E) até a próxima data","Janela de reclamação encerrada: novo pedido ou modelo G"))),IF(I6="Atendido","Concluído: registre a resposta no Log",IF(OR(I6="Negado",I6="Atendido em parte"),"Recorrer (modelo B ou D) até a próxima data","Preencha o resultado da resposta")))))
G7: =IF(E7="","",E7+IF(F7="Sim",30,20)) | L7: =IF(E7="","",IF(AND(K7<>"",OR(H7="",K7>=H7)),IF(J7="CMRI","",K7+5),IF(H7="",IF(TODAY()<=G7,G7,IF(TODAY()<E7+30,E7+30,E7+40)),IF(OR(I7="Negado",I7="Atendido em parte"),H7+10,"")))) | M7: =IF(L7="","",L7-TODAY()) | N7: =IF(E7="","",IF(AND(K7<>"",OR(H7="",K7>=H7)),IF(J7="CMRI","Aguardar a CMRI (até a 3ª reunião mensal depois da autuação)","Aguardar decisão do recurso ou da reclamação"),IF(H7="",IF(TODAY()<=G7,"Aguardar resposta do órgão",IF(TODAY()<E7+30,"Prazo vencido: reclamação (modelo E) a partir da próxima data",IF(TODAY()<=E7+40,"Fazer reclamação (modelo E) até a próxima data","Janela de reclamação encerrada: novo pedido ou modelo G"))),IF(I7="Atendido","Concluído: registre a resposta no Log",IF(OR(I7="Negado",I7="Atendido em parte"),"Recorrer (modelo B ou D) até a próxima data","Preencha o resultado da resposta")))))
G8: =IF(E8="","",E8+IF(F8="Sim",30,20)) | L8: =IF(E8="","",IF(AND(K8<>"",OR(H8="",K8>=H8)),IF(J8="CMRI","",K8+5),IF(H8="",IF(TODAY()<=G8,G8,IF(TODAY()<E8+30,E8+30,E8+40)),IF(OR(I8="Negado",I8="Atendido em parte"),H8+10,"")))) | M8: =IF(L8="","",L8-TODAY()) | N8: =IF(E8="","",IF(AND(K8<>"",OR(H8="",K8>=H8)),IF(J8="CMRI","Aguardar a CMRI (até a 3ª reunião mensal depois da autuação)","Aguardar decisão do recurso ou da reclamação"),IF(H8="",IF(TODAY()<=G8,"Aguardar resposta do órgão",IF(TODAY()<E8+30,"Prazo vencido: reclamação (modelo E) a partir da próxima data",IF(TODAY()<=E8+40,"Fazer reclamação (modelo E) até a próxima data","Janela de reclamação encerrada: novo pedido ou modelo G"))),IF(I8="Atendido","Concluído: registre a resposta no Log",IF(OR(I8="Negado",I8="Atendido em parte"),"Recorrer (modelo B ou D) até a próxima data","Preencha o resultado da resposta")))))
G9: =IF(E9="","",E9+IF(F9="Sim",30,20)) | L9: =IF(E9="","",IF(AND(K9<>"",OR(H9="",K9>=H9)),IF(J9="CMRI","",K9+5),IF(H9="",IF(TODAY()<=G9,G9,IF(TODAY()<E9+30,E9+30,E9+40)),IF(OR(I9="Negado",I9="Atendido em parte"),H9+10,"")))) | M9: =IF(L9="","",L9-TODAY()) | N9: =IF(E9="","",IF(AND(K9<>"",OR(H9="",K9>=H9)),IF(J9="CMRI","Aguardar a CMRI (até a 3ª reunião mensal depois da autuação)","Aguardar decisão do recurso ou da reclamação"),IF(H9="",IF(TODAY()<=G9,"Aguardar resposta do órgão",IF(TODAY()<E9+30,"Prazo vencido: reclamação (modelo E) a partir da próxima data",IF(TODAY()<=E9+40,"Fazer reclamação (modelo E) até a próxima data","Janela de reclamação encerrada: novo pedido ou modelo G"))),IF(I9="Atendido","Concluído: registre a resposta no Log",IF(OR(I9="Negado",I9="Atendido em parte"),"Recorrer (modelo B ou D) até a próxima data","Preencha o resultado da resposta")))))
G10: =IF(E10="","",E10+IF(F10="Sim",30,20)) | L10: =IF(E10="","",IF(AND(K10<>"",OR(H10="",K10>=H10)),IF(J10="CMRI","",K10+5),IF(H10="",IF(TODAY()<=G10,G10,IF(TODAY()<E10+30,E10+30,E10+40)),IF(OR(I10="Negado",I10="Atendido em parte"),H10+10,"")))) | M10: =IF(L10="","",L10-TODAY()) | N10: =IF(E10="","",IF(AND(K10<>"",OR(H10="",K10>=H10)),IF(J10="CMRI","Aguardar a CMRI (até a 3ª reunião mensal depois da autuação)","Aguardar decisão do recurso ou da reclamação"),IF(H10="",IF(TODAY()<=G10,"Aguardar resposta do órgão",IF(TODAY()<E10+30,"Prazo vencido: reclamação (modelo E) a partir da próxima data",IF(TODAY()<=E10+40,"Fazer reclamação (modelo E) até a próxima data","Janela de reclamação encerrada: novo pedido ou modelo G"))),IF(I10="Atendido","Concluído: registre a resposta no Log",IF(OR(I10="Negado",I10="Atendido em parte"),"Recorrer (modelo B ou D) até a próxima data","Preencha o resultado da resposta")))))
G11: =IF(E11="","",E11+IF(F11="Sim",30,20)) | L11: =IF(E11="","",IF(AND(K11<>"",OR(H11="",K11>=H11)),IF(J11="CMRI","",K11+5),IF(H11="",IF(TODAY()<=G11,G11,IF(TODAY()<E11+30,E11+30,E11+40)),IF(OR(I11="Negado",I11="Atendido em parte"),H11+10,"")))) | M11: =IF(L11="","",L11-TODAY()) | N11: =IF(E11="","",IF(AND(K11<>"",OR(H11="",K11>=H11)),IF(J11="CMRI","Aguardar a CMRI (até a 3ª reunião mensal depois da autuação)","Aguardar decisão do recurso ou da reclamação"),IF(H11="",IF(TODAY()<=G11,"Aguardar resposta do órgão",IF(TODAY()<E11+30,"Prazo vencido: reclamação (modelo E) a partir da próxima data",IF(TODAY()<=E11+40,"Fazer reclamação (modelo E) até a próxima data","Janela de reclamação encerrada: novo pedido ou modelo G"))),IF(I11="Atendido","Concluído: registre a resposta no Log",IF(OR(I11="Negado",I11="Atendido em parte"),"Recorrer (modelo B ou D) até a próxima data","Preencha o resultado da resposta")))))
G12: =IF(E12="","",E12+IF(F12="Sim",30,20)) | L12: =IF(E12="","",IF(AND(K12<>"",OR(H12="",K12>=H12)),IF(J12="CMRI","",K12+5),IF(H12="",IF(TODAY()<=G12,G12,IF(TODAY()<E12+30,E12+30,E12+40)),IF(OR(I12="Negado",I12="Atendido em parte"),H12+10,"")))) | M12: =IF(L12="","",L12-TODAY()) | N12: =IF(E12="","",IF(AND(K12<>"",OR(H12="",K12>=H12)),IF(J12="CMRI","Aguardar a CMRI (até a 3ª reunião mensal depois da autuação)","Aguardar decisão do recurso ou da reclamação"),IF(H12="",IF(TODAY()<=G12,"Aguardar resposta do órgão",IF(TODAY()<E12+30,"Prazo vencido: reclamação (modelo E) a partir da próxima data",IF(TODAY()<=E12+40,"Fazer reclamação (modelo E) até a próxima data","Janela de reclamação encerrada: novo pedido ou modelo G"))),IF(I12="Atendido","Concluído: registre a resposta no Log",IF(OR(I12="Negado",I12="Atendido em parte"),"Recorrer (modelo B ou D) até a próxima data","Preencha o resultado da resposta")))))
G13: =IF(E13="","",E13+IF(F13="Sim",30,20)) | L13: =IF(E13="","",IF(AND(K13<>"",OR(H13="",K13>=H13)),IF(J13="CMRI","",K13+5),IF(H13="",IF(TODAY()<=G13,G13,IF(TODAY()<E13+30,E13+30,E13+40)),IF(OR(I13="Negado",I13="Atendido em parte"),H13+10,"")))) | M13: =IF(L13="","",L13-TODAY()) | N13: =IF(E13="","",IF(AND(K13<>"",OR(H13="",K13>=H13)),IF(J13="CMRI","Aguardar a CMRI (até a 3ª reunião mensal depois da autuação)","Aguardar decisão do recurso ou da reclamação"),IF(H13="",IF(TODAY()<=G13,"Aguardar resposta do órgão",IF(TODAY()<E13+30,"Prazo vencido: reclamação (modelo E) a partir da próxima data",IF(TODAY()<=E13+40,"Fazer reclamação (modelo E) até a próxima data","Janela de reclamação encerrada: novo pedido ou modelo G"))),IF(I13="Atendido","Concluído: registre a resposta no Log",IF(OR(I13="Negado",I13="Atendido em parte"),"Recorrer (modelo B ou D) até a próxima data","Preencha o resultado da resposta")))))
G14: =IF(E14="","",E14+IF(F14="Sim",30,20)) | L14: =IF(E14="","",IF(AND(K14<>"",OR(H14="",K14>=H14)),IF(J14="CMRI","",K14+5),IF(H14="",IF(TODAY()<=G14,G14,IF(TODAY()<E14+30,E14+30,E14+40)),IF(OR(I14="Negado",I14="Atendido em parte"),H14+10,"")))) | M14: =IF(L14="","",L14-TODAY()) | N14: =IF(E14="","",IF(AND(K14<>"",OR(H14="",K14>=H14)),IF(J14="CMRI","Aguardar a CMRI (até a 3ª reunião mensal depois da autuação)","Aguardar decisão do recurso ou da reclamação"),IF(H14="",IF(TODAY()<=G14,"Aguardar resposta do órgão",IF(TODAY()<E14+30,"Prazo vencido: reclamação (modelo E) a partir da próxima data",IF(TODAY()<=E14+40,"Fazer reclamação (modelo E) até a próxima data","Janela de reclamação encerrada: novo pedido ou modelo G"))),IF(I14="Atendido","Concluído: registre a resposta no Log",IF(OR(I14="Negado",I14="Atendido em parte"),"Recorrer (modelo B ou D) até a próxima data","Preencha o resultado da resposta")))))
G15: =IF(E15="","",E15+IF(F15="Sim",30,20)) | L15: =IF(E15="","",IF(AND(K15<>"",OR(H15="",K15>=H15)),IF(J15="CMRI","",K15+5),IF(H15="",IF(TODAY()<=G15,G15,IF(TODAY()<E15+30,E15+30,E15+40)),IF(OR(I15="Negado",I15="Atendido em parte"),H15+10,"")))) | M15: =IF(L15="","",L15-TODAY()) | N15: =IF(E15="","",IF(AND(K15<>"",OR(H15="",K15>=H15)),IF(J15="CMRI","Aguardar a CMRI (até a 3ª reunião mensal depois da autuação)","Aguardar decisão do recurso ou da reclamação"),IF(H15="",IF(TODAY()<=G15,"Aguardar resposta do órgão",IF(TODAY()<E15+30,"Prazo vencido: reclamação (modelo E) a partir da próxima data",IF(TODAY()<=E15+40,"Fazer reclamação (modelo E) até a próxima data","Janela de reclamação encerrada: novo pedido ou modelo G"))),IF(I15="Atendido","Concluído: registre a resposta no Log",IF(OR(I15="Negado",I15="Atendido em parte"),"Recorrer (modelo B ou D) até a próxima data","Preencha o resultado da resposta")))))
